Workbook

Sheet Importante
A2: Aviso Importante
A4: Região de SP desconsiderar a coluna de ST da aba pedidos
A6: Essa planilha não é válida para clientes do Simples Nacional

Sheet FOLHA DE PEDIDO 
S2: À Vista | T2: 119 | U2: AC
S3: 14 | U3: AL
S4: 21 | U4: AM
S5: 28 | U5: AP
F6: RO | S6: 35 | U6: BA
S7: 42 | U7: CE
G8: Inserir 20% de desconto em todos os itens | S8: 49 | U8: DF
C9: 119 | F9: À Vista | G9: R$ 3.000,00: pequeno e médio varejo | S9: 56 | U9: ES
G10: R$ 5.000,00: supermercados e grandes redes | S10: 60 | U10: RO
G11: Observação do pedido: | S11: 75 | U11: MA
C12: =SUM($N$21:$N$328) -> 0 | S12: 90 | U12: MG
U13: MS
U14: MT
U15: PA
U16: PB
U17: PE
U18: PI
U19: PR
B20: CÓDIGO PRODUTO | C20: DESCRIÇÃO | D20: M.V. | E20: COR | F20: QTDE | G20: PREÇO TABELA | H20: DESC. | I20: PREÇO UNI. | J20: IPI | K20: ST | L20: PREÇO C/ IPI | M20: PREÇO C/ ST | N20: VALOR LÍQ. | O20: VALOR BRUTO | P20: NCM | U20: RJ
C21: =IFERROR((IF(B21="","",IF($F$6="","Informar UF / Tabela / Prazo de Pagamento",IF($F$9="","Informar UF / Tabela / Prazo de Pagamento",IF($C$9="","Informar UF / Tabela / Prazo de Pagamento",VLOOKUP(B21,'Tabela 130 '!$A$5:$T$1001,2,FALSE)))))),"REF. NÃO CADASTRADA NA TABELA") | D21: =IF('FOLHA DE PEDIDO '!B21="","",IF(C21="REF. NÃO CADASTRADA NA TABELA","",VLOOKUP(B21,'Tabela 130 '!$A$5:$AI$801,3,FALSE))) | G21: =IFERROR(IF(C21="REF. NÃO CADASTRADA NA TABELA","",IF($C$9="","",IF($F$9="","",IF(B21="","",IF($C$9=119,VLOOKUP(B21,'Tabela 130 '!$A$5:$T$2711,MATCH($F$9,'Tabela 130 '!$A$5:$T$5,0),FALSE),IF($C$9=553,VLOOKUP(B21,#REF!,MATCH($F$9,#REF!,0),FALSE),IF($C$9=552,VLOOKUP(B21,#REF!,MATCH($F$9,#REF!,0),FALSE),IF($C$9=551,VLOOKUP(B21,#REF!,MATCH($F$9,#REF!,0),FALSE))))))))),"REF. NÃO CADASTRADA NA TABELA") | H21: 0.2 | I21: =IFERROR(IF(B21=0,"",(G21-(G21*H21))),"") | J21: =IF(B21="","",IF(C21="REF. NÃO CADASTRADA NA TABELA","",VLOOKUP(B21,#REF!,7,FALSE))) | K21: =IF($F$6="","",IF(B21="","",IF(C21="REF. NÃO CADASTRADA NA TABELA","",IFERROR(VLOOKUP(B21,#REF!,VLOOKUP($F$6,'BASE CONTÁBIL'!N:O,2,FALSE),FALSE),0)))) | L21: =IFERROR(I21*(1+J21%),"") | M21: =IFERROR(IF(B21="","",L21*(1+K21)),"") | N21: =IFERROR(IF(B21="","",IF(F21="","",F21*I21)),"") | O21: =IFERROR(IF(B21="","",IF(F21="","",M21*F21)),"") | P21: =VLOOKUP(B21,#REF!,17,FALSE) -> #REF! | U21: SP
C22: =IFERROR((IF(B22="","",IF($F$6="","Informar UF / Tabela / Prazo de Pagamento",IF($F$9="","Informar UF / Tabela / Prazo de Pagamento",IF($C$9="","Informar UF / Tabela / Prazo de Pagamento",VLOOKUP(B22,'Tabela 130 '!$A$5:$T$1001,2,FALSE)))))),"REF. NÃO CADASTRADA NA TABELA") | D22: =IF('FOLHA DE PEDIDO '!B22="","",IF(C22="REF. NÃO CADASTRADA NA TABELA","",VLOOKUP(B22,'Tabela 130 '!$A$5:$AI$801,3,FALSE))) | G22: =IFERROR(IF(C22="REF. NÃO CADASTRADA NA TABELA","",IF($C$9="","",IF($F$9="","",IF(B22="","",IF($C$9=119,VLOOKUP(B22,'Tabela 130 '!$A$5:$T$2711,MATCH($F$9,'Tabela 130 '!$A$5:$T$5,0),FALSE),IF($C$9=553,VLOOKUP(B22,#REF!,MATCH($F$9,#REF!,0),FALSE),IF($C$9=552,VLOOKUP(B22,#REF!,MATCH($F$9,#REF!,0),FALSE),IF($C$9=551,VLOOKUP(B22,#REF!,MATCH($F$9,#REF!,0),FALSE))))))))),"REF. NÃO CADASTRADA NA TABELA") | I22: =IFERROR(IF(B22=0,"",(G22-(G22*H22))),"") | J22: =IF(B22="","",IF(C22="REF. NÃO CADASTRADA NA TABELA","",VLOOKUP(B22,#REF!,7,FALSE))) | K22: =IF($F$6="","",IF(B22="","",IF(C22="REF. NÃO CADASTRADA NA TABELA","",IFERROR(VLOOKUP(B22,#REF!,VLOOKUP($F$6,'BASE CONTÁBIL'!N:O,2,FALSE),FALSE),0)))) | L22: =IFERROR(I22*(1+J22%),"") | M22: =IFERROR(IF(B22="","",L22*(1+K22)),"") | N22: =IFERROR(IF(B22="","",IF(F22="","",F22*I22)),"") | O22: =IFERROR(IF(B22="","",IF(F22="","",M22*F22)),"") | P22: =VLOOKUP(B22,#REF!,17,FALSE) -> #REF! | U22: TO
C23: =IFERROR((IF(B23="","",IF($F$6="","Informar UF / Tabela / Prazo de Pagamento",IF($F$9="","Informar UF / Tabela / Prazo de Pagamento",IF($C$9="","Informar UF / Tabela / Prazo de Pagamento",VLOOKUP(B23,'Tabela 130 '!$A$5:$T$1001,2,FALSE)))))),"REF. NÃO CADASTRADA NA TABELA") | D23: =IF('FOLHA DE PEDIDO '!B23="","",IF(C23="REF. NÃO CADASTRADA NA TABELA","",VLOOKUP(B23,'Tabela 130 '!$A$5:$AI$801,3,FALSE))) | G23: =IFERROR(IF(C23="REF. NÃO CADASTRADA NA TABELA","",IF($C$9="","",IF($F$9="","",IF(B23="","",IF($C$9=119,VLOOKUP(B23,'Tabela 130 '!$A$5:$T$2711,MATCH($F$9,'Tabela 130 '!$A$5:$T$5,0),FALSE),IF($C$9=553,VLOOKUP(B23,#REF!,MATCH($F$9,#REF!,0),FALSE),IF($C$9=552,VLOOKUP(B23,#REF!,MATCH($F$9,#REF!,0),FALSE),IF($C$9=551,VLOOKUP(B23,#REF!,MATCH($F$9,#REF!,0),FALSE))))))))),"REF. NÃO CADASTRADA NA TABELA") | I23: =IFERROR(IF(B23=0,"",(G23-(G23*H23))),"") | J23: =IF(B23="","",IF(C23="REF. NÃO CADASTRADA NA TABELA","",VLOOKUP(B23,#REF!,7,FALSE))) | K23: =IF($F$6="","",IF(B23="","",IF(C23="REF. NÃO CADASTRADA NA TABELA","",IFERROR(VLOOKUP(B23,#REF!,VLOOKUP($F$6,'BASE CONTÁBIL'!N:O,2,FALSE),FALSE),0)))) | L23: =IFERROR(I23*(1+J23%),"") | M23: =IFERROR(IF(B23="","",L23*(1+K23)),"") | N23: =IFERROR(IF(B23="","",IF(F23="","",F23*I23)),"") | O23: =IFERROR(IF(B23="","",IF(F23="","",M23*F23)),"") | P23: =VLOOKUP(B23,#REF!,17,FALSE) -> #REF!
C24: =IFERROR((IF(B24="","",IF($F$6="","Informar UF / Tabela / Prazo de Pagamento",IF($F$9="","Informar UF / Tabela / Prazo de Pagamento",IF($C$9="","Informar UF / Tabela / Prazo de Pagamento",VLOOKUP(B24,'Tabela 130 '!$A$5:$T$1001,2,FALSE)))))),"REF. NÃO CADASTRADA NA TABELA") | D24: =IF('FOLHA DE PEDIDO '!B24="","",IF(C24="REF. NÃO CADASTRADA NA TABELA","",VLOOKUP(B24,'Tabela 130 '!$A$5:$AI$801,3,FALSE))) | G24: =IFERROR(IF(C24="REF. NÃO CADASTRADA NA TABELA","",IF($C$9="","",IF($F$9="","",IF(B24="","",IF($C$9=119,VLOOKUP(B24,'Tabela 130 '!$A$5:$T$2711,MATCH($F$9,'Tabela 130 '!$A$5:$T$5,0),FALSE),IF($C$9=553,VLOOKUP(B24,#REF!,MATCH($F$9,#REF!,0),FALSE),IF($C$9=552,VLOOKUP(B24,#REF!,MATCH($F$9,#REF!,0),FALSE),IF($C$9=551,VLOOKUP(B24,#REF!,MATCH($F$9,#REF!,0),FALSE))))))))),"REF. NÃO CADASTRADA NA TABELA") | I24: =IFERROR(IF(B24=0,"",(G24-(G24*H24))),"") | J24: =IF(B24="","",IF(C24="REF. NÃO CADASTRADA NA TABELA","",VLOOKUP(B24,#REF!,7,FALSE))) | K24: =IF($F$6="","",IF(B24="","",IF(C24="REF. NÃO CADASTRADA NA TABELA","",IFERROR(VLOOKUP(B24,#REF!,VLOOKUP($F$6,'BASE CONTÁBIL'!N:O,2,FALSE),FALSE),0)))) | L24: =IFERROR(I24*(1+J24%),"") | M24: =IFERROR(IF(B24="","",L24*(1+K24)),"") | N24: =IFERROR(IF(B24="","",IF(F24="","",F24*I24)),"") | O24: =IFERROR(IF(B24="","",IF(F24="","",M24*F24)),"") | P24: =VLOOKUP(B24,#REF!,17,FALSE) -> #REF!
G25: =IFERROR(IF(C25="REF. NÃO CADASTRADA NA TABELA","",IF($C$9="","",IF($F$9="","",IF(B25="","",IF($C$9=119,VLOOKUP(B25,'Tabela 130 '!$A$5:$T$2711,MATCH($F$9,'Tabela 130 '!$A$5:$T$5,0),FALSE),IF($C$9=553,VLOOKUP(B25,#REF!,MATCH($F$9,#REF!,0),FALSE),IF($C$9=552,VLOOKUP(B25,#REF!,MATCH($F$9,#REF!,0),FALSE),IF($C$9=551,VLOOKUP(B25,#REF!,MATCH($F$9,#REF!,0),FALSE))))))))),"REF. NÃO CADASTRADA NA TABELA") | I25: =IFERROR(IF(B25=0,"",(G25-(G25*H25))),"") | J25: =IF(B25="","",IF(C25="REF. NÃO CADASTRADA NA TABELA","",VLOOKUP(B25,#REF!,7,FALSE))) | K25: =IF($F$6="","",IF(B25="","",IF(C25="REF. NÃO CADASTRADA NA TABELA","",IFERROR(VLOOKUP(B25,#REF!,VLOOKUP($F$6,'BASE CONTÁBIL'!N:O,2,FALSE),FALSE),0)))) | L25: =IFERROR(I25*(1+J25%),"") | M25: =IFERROR(IF(B25="","",L25*(1+K25)),"") | N25: =IFERROR(IF(B25="","",IF(F25="","",F25*I25)),"") | O25: =IFERROR(IF(B25="","",IF(F25="","",M25*F25)),"") | P25: =VLOOKUP(B25,#REF!,17,FALSE) -> #REF!
C26: =IFERROR((IF(B26="","",IF($F$6="","Informar UF / Tabela / Prazo de Pagamento",IF($F$9="","Informar UF / Tabela / Prazo de Pagamento",IF($C$9="","Informar UF / Tabela / Prazo de Pagamento",VLOOKUP(B26,'Tabela 130 '!$A$5:$T$1001,2,FALSE)))))),"REF. NÃO CADASTRADA NA TABELA") | D26: =IF('FOLHA DE PEDIDO '!B26="","",IF(C26="REF. NÃO CADASTRADA NA TABELA","",VLOOKUP(B26,'Tabela 130 '!$A$5:$AI$801,3,FALSE))) | G26: =IFERROR(IF(C26="REF. NÃO CADASTRADA NA TABELA","",IF($C$9="","",IF($F$9="","",IF(B26="","",IF($C$9=119,VLOOKUP(B26,'Tabela 130 '!$A$5:$T$2711,MATCH($F$9,'Tabela 130 '!$A$5:$T$5,0),FALSE),IF($C$9=553,VLOOKUP(B26,#REF!,MATCH($F$9,#REF!,0),FALSE),IF($C$9=552,VLOOKUP(B26,#REF!,MATCH($F$9,#REF!,0),FALSE),IF($C$9=551,VLOOKUP(B26,#REF!,MATCH($F$9,#REF!,0),FALSE))))))))),"REF. NÃO CADASTRADA NA TABELA") | I26: =IFERROR(IF(B26=0,"",(G26-(G26*H26))),"") | J26: =IF(B26="","",IF(C26="REF. NÃO CADASTRADA NA TABELA","",VLOOKUP(B26,#REF!,7,FALSE))) | K26: =IF($F$6="","",IF(B26="","",IF(C26="REF. NÃO CADASTRADA NA TABELA","",IFERROR(VLOOKUP(B26,#REF!,VLOOKUP($F$6,'BASE CONTÁBIL'!N:O,2,FALSE),FALSE),0)))) | L26: =IFERROR(I26*(1+J26%),"") | M26: =IFERROR(IF(B26="","",L26*(1+K26)),"") | N26: =IFERROR(IF(B26="","",IF(F26="","",F26*I26)),"") | O26: =IFERROR(IF(B26="","",IF(F26="","",M26*F26)),"") | P26: =VLOOKUP(B26,#REF!,17,FALSE) -> #REF!
C27: =IFERROR((IF(B27="","",IF($F$6="","Informar UF / Tabela / Prazo de Pagamento",IF($F$9="","Informar UF / Tabela / Prazo de Pagamento",IF($C$9="","Informar UF / Tabela / Prazo de Pagamento",VLOOKUP(B27,'Tabela 130 '!$A$5:$T$1001,2,FALSE)))))),"REF. NÃO CADASTRADA NA TABELA") | D27: =IF('FOLHA DE PEDIDO '!B27="","",IF(C27="REF. NÃO CADASTRADA NA TABELA","",VLOOKUP(B27,'Tabela 130 '!$A$5:$AI$801,3,FALSE))) | G27: =IFERROR(IF(C27="REF. NÃO CADASTRADA NA TABELA","",IF($C$9="","",IF($F$9="","",IF(B27="","",IF($C$9=119,VLOOKUP(B27,'Tabela 130 '!$A$5:$T$2711,MATCH($F$9,'Tabela 130 '!$A$5:$T$5,0),FALSE),IF($C$9=553,VLOOKUP(B27,#REF!,MATCH($F$9,#REF!,0),FALSE),IF($C$9=552,VLOOKUP(B27,#REF!,MATCH($F$9,#REF!,0),FALSE),IF($C$9=551,VLOOKUP(B27,#REF!,MATCH($F$9,#REF!,0),FALSE))))))))),"REF. NÃO CADASTRADA NA TABELA") | I27: =IFERROR(IF(B27=0,"",(G27-(G27*H27))),"") | J27: =IF(B27="","",IF(C27="REF. NÃO CADASTRADA NA TABELA","",VLOOKUP(B27,#REF!,7,FALSE))) | K27: =IF($F$6="","",IF(B27="","",IF(C27="REF. NÃO CADASTRADA NA TABELA","",IFERROR(VLOOKUP(B27,#REF!,VLOOKUP($F$6,'BASE CONTÁBIL'!N:O,2,FALSE),FALSE),0)))) | L27: =IFERROR(I27*(1+J27%),"") | M27: =IFERROR(IF(B27="","",L27*(1+K27)),"") | N27: =IFERROR(IF(B27="","",IF(F27="","",F27*I27)),"") | O27: =IFERROR(IF(B27="","",IF(F27="","",M27*F27)),"") | P27: =VLOOKUP(B27,#REF!,17,FALSE) -> #REF!
C28: =IFERROR((IF(B28="","",IF($F$6="","Informar UF / Tabela / Prazo de Pagamento",IF($F$9="","Informar UF / Tabela / Prazo de Pagamento",IF($C$9="","Informar UF / Tabela / Prazo de Pagamento",VLOOKUP(B28,'Tabela 130 '!$A$5:$T$1001,2,FALSE)))))),"REF. NÃO CADASTRADA NA TABELA") | D28: =IF('FOLHA DE PEDIDO '!B28="","",IF(C28="REF. NÃO CADASTRADA NA TABELA","",VLOOKUP(B28,'Tabela 130 '!$A$5:$AI$801,3,FALSE))) | G28: =IFERROR(IF(C28="REF. NÃO CADASTRADA NA TABELA","",IF($C$9="","",IF($F$9="","",IF(B28="","",IF($C$9=119,VLOOKUP(B28,'Tabela 130 '!$A$5:$T$2711,MATCH($F$9,'Tabela 130 '!$A$5:$T$5,0),FALSE),IF($C$9=553,VLOOKUP(B28,#REF!,MATCH($F$9,#REF!,0),FALSE),IF($C$9=552,VLOOKUP(B28,#REF!,MATCH($F$9,#REF!,0),FALSE),IF($C$9=551,VLOOKUP(B28,#REF!,MATCH($F$9,#REF!,0),FALSE))))))))),"REF. NÃO CADASTRADA NA TABELA") | I28: =IFERROR(IF(B28=0,"",(G28-(G28*H28))),"") | J28: =IF(B28="","",IF(C28="REF. NÃO CADASTRADA NA TABELA","",VLOOKUP(B28,#REF!,7,FALSE))) | K28: =IF($F$6="","",IF(B28="","",IF(C28="REF. NÃO CADASTRADA NA TABELA","",IFERROR(VLOOKUP(B28,#REF!,VLOOKUP($F$6,'BASE CONTÁBIL'!N:O,2,FALSE),FALSE),0)))) | L28: =IFERROR(I28*(1+J28%),"") | M28: =IFERROR(IF(B28="","",L28*(1+K28)),"") | N28: =IFERROR(IF(B28="","",IF(F28="","",F28*I28)),"") | O28: =IFERROR(IF(B28="","",IF(F28="","",M28*F28)),"") | P28: =VLOOKUP(B28,#REF!,17,FALSE) -> #REF!
C29: =IFERROR((IF(B29="","",IF($F$6="","Informar UF / Tabela / Prazo de Pagamento",IF($F$9="","Informar UF / Tabela / Prazo de Pagamento",IF($C$9="","Informar UF / Tabela / Prazo de Pagamento",VLOOKUP(B29,'Tabela 130 '!$A$5:$T$1001,2,FALSE)))))),"REF. NÃO CADASTRADA NA TABELA") | D29: =IF('FOLHA DE PEDIDO '!B29="","",IF(C29="REF. NÃO CADASTRADA NA TABELA","",VLOOKUP(B29,'Tabela 130 '!$A$5:$AI$801,3,FALSE))) | G29: =IFERROR(IF(C29="REF. NÃO CADASTRADA NA TABELA","",IF($C$9="","",IF($F$9="","",IF(B29="","",IF($C$9=119,VLOOKUP(B29,'Tabela 130 '!$A$5:$T$2711,MATCH($F$9,'Tabela 130 '!$A$5:$T$5,0),FALSE),IF($C$9=553,VLOOKUP(B29,#REF!,MATCH($F$9,#REF!,0),FALSE),IF($C$9=552,VLOOKUP(B29,#REF!,MATCH($F$9,#REF!,0),FALSE),IF($C$9=551,VLOOKUP(B29,#REF!,MATCH($F$9,#REF!,0),FALSE))))))))),"REF. NÃO CADASTRADA NA TABELA") | I29: =IFERROR(IF(B29=0,"",(G29-(G29*H29))),"") | J29: =IF(B29="","",IF(C29="REF. NÃO CADASTRADA NA TABELA","",VLOOKUP(B29,#REF!,7,FALSE))) | K29: =IF($F$6="","",IF(B29="","",IF(C29="REF. NÃO CADASTRADA NA TABELA","",IFERROR(VLOOKUP(B29,#REF!,VLOOKUP($F$6,'BASE CONTÁBIL'!N:O,2,FALSE),FALSE),0)))) | L29: =IFERROR(I29*(1+J29%),"") | M29: =IFERROR(IF(B29="","",L29*(1+K29)),"") | N29: =IFERROR(IF(B29="","",IF(F29="","",F29*I29)),"") | O29: =IFERROR(IF(B29="","",IF(F29="","",M29*F29)),"") | P29: =VLOOKUP(B29,#REF!,17,FALSE) -> #REF!
C30: =IFERROR((IF(B30="","",IF($F$6="","Informar UF / Tabela / Prazo de Pagamento",IF($F$9="","Informar UF / Tabela / Prazo de Pagamento",IF($C$9="","Informar UF / Tabela / Prazo de Pagamento",VLOOKUP(B30,'Tabela 130 '!$A$5:$T$1001,2,FALSE)))))),"REF. NÃO CADASTRADA NA TABELA") | D30: =IF('FOLHA DE PEDIDO '!B30="","",IF(C30="REF. NÃO CADASTRADA NA TABELA","",VLOOKUP(B30,'Tabela 130 '!$A$5:$AI$801,3,FALSE))) | G30: =IFERROR(IF(C30="REF. NÃO CADASTRADA NA TABELA","",IF($C$9="","",IF($F$9="","",IF(B30="","",IF($C$9=119,VLOOKUP(B30,'Tabela 130 '!$A$5:$T$2711,MATCH($F$9,'Tabela 130 '!$A$5:$T$5,0),FALSE),IF($C$9=553,VLOOKUP(B30,#REF!,MATCH($F$9,#REF!,0),FALSE),IF($C$9=552,VLOOKUP(B30,#REF!,MATCH($F$9,#REF!,0),FALSE),IF($C$9=551,VLOOKUP(B30,#REF!,MATCH($F$9,#REF!,0),FALSE))))))))),"REF. NÃO CADASTRADA NA TABELA") | I30: =IFERROR(IF(B30=0,"",(G30-(G30*H30))),"") | J30: =IF(B30="","",IF(C30="REF. NÃO CADASTRADA NA TABELA","",VLOOKUP(B30,#REF!,7,FALSE))) | K30: =IF($F$6="","",IF(B30="","",IF(C30="REF. NÃO CADASTRADA NA TABELA","",IFERROR(VLOOKUP(B30,#REF!,VLOOKUP($F$6,'BASE CONTÁBIL'!N:O,2,FALSE),FALSE),0)))) | L30: =IFERROR(I30*(1+J30%),"") | M30: =IFERROR(IF(B30="","",L30*(1+K30)),"") | N30: =IFERROR(IF(B30="","",IF(F30="","",F30*I30)),"") | O30: =IFERROR(IF(B30="","",IF(F30="","",M30*F30)),"") | P30: =VLOOKUP(B30,#REF!,17,FALSE) -> #REF!
C31: =IFERROR((IF(B31="","",IF($F$6="","Informar UF / Tabela / Prazo de Pagamento",IF($F$9="","Informar UF / Tabela / Prazo de Pagamento",IF($C$9="","Informar UF / Tabela / Prazo de Pagamento",VLOOKUP(B31,'Tabela 130 '!$A$5:$T$1001,2,FALSE)))))),"REF. NÃO CADASTRADA NA TABELA") | D31: =IF('FOLHA DE PEDIDO '!B31="","",IF(C31="REF. NÃO CADASTRADA NA TABELA","",VLOOKUP(B31,'Tabela 130 '!$A$5:$AI$801,3,FALSE))) | G31: =IFERROR(IF(C31="REF. NÃO CADASTRADA NA TABELA","",IF($C$9="","",IF($F$9="","",IF(B31="","",IF($C$9=119,VLOOKUP(B31,'Tabela 130 '!$A$5:$T$2711,MATCH($F$9,'Tabela 130 '!$A$5:$T$5,0),FALSE),IF($C$9=553,VLOOKUP(B31,#REF!,MATCH($F$9,#REF!,0),FALSE),IF($C$9=552,VLOOKUP(B31,#REF!,MATCH($F$9,#REF!,0),FALSE),IF($C$9=551,VLOOKUP(B31,#REF!,MATCH($F$9,#REF!,0),FALSE))))))))),"REF. NÃO CADASTRADA NA TABELA") | I31: =IFERROR(IF(B31=0,"",(G31-(G31*H31))),"") | J31: =IF(B31="","",IF(C31="REF. NÃO CADASTRADA NA TABELA","",VLOOKUP(B31,#REF!,7,FALSE))) | K31: =IF($F$6="","",IF(B31="","",IF(C31="REF. NÃO CADASTRADA NA TABELA","",IFERROR(VLOOKUP(B31,#REF!,VLOOKUP($F$6,'BASE CONTÁBIL'!N:O,2,FALSE),FALSE),0)))) | L31: =IFERROR(I31*(1+J31%),"") | M31: =IFERROR(IF(B31="","",L31*(1+K31)),"") | N31: =IFERROR(IF(B31="","",IF(F31="","",F31*I31)),"") | O31: =IFERROR(IF(B31="","",IF(F31="","",M31*F31)),"") | P31: =VLOOKUP(B31,#REF!,17,FALSE) -> #REF!
C32: =IFERROR((IF(B32="","",IF($F$6="","Informar UF / Tabela / Prazo de Pagamento",IF($F$9="","Informar UF / Tabela / Prazo de Pagamento",IF($C$9="","Informar UF / Tabela / Prazo de Pagamento",VLOOKUP(B32,'Tabela 130 '!$A$5:$T$1001,2,FALSE)))))),"REF. NÃO CADASTRADA NA TABELA") | D32: =IF('FOLHA DE PEDIDO '!B32="","",IF(C32="REF. NÃO CADASTRADA NA TABELA","",VLOOKUP(B32,'Tabela 130 '!$A$5:$AI$801,3,FALSE))) | G32: =IFERROR(IF(C32="REF. NÃO CADASTRADA NA TABELA","",IF($C$9="","",IF($F$9="","",IF(B32="","",IF($C$9=119,VLOOKUP(B32,'Tabela 130 '!$A$5:$T$2711,MATCH($F$9,'Tabela 130 '!$A$5:$T$5,0),FALSE),IF($C$9=553,VLOOKUP(B32,#REF!,MATCH($F$9,#REF!,0),FALSE),IF($C$9=552,VLOOKUP(B32,#REF!,MATCH($F$9,#REF!,0),FALSE),IF($C$9=551,VLOOKUP(B32,#REF!,MATCH($F$9,#REF!,0),FALSE))))))))),"REF. NÃO CADASTRADA NA TABELA") | I32: =IFERROR(IF(B32=0,"",(G32-(G32*H32))),"") | J32: =IF(B32="","",IF(C32="REF. NÃO CADASTRADA NA TABELA","",VLOOKUP(B32,#REF!,7,FALSE))) | K32: =IF($F$6="","",IF(B32="","",IF(C32="REF. NÃO CADASTRADA NA TABELA","",IFERROR(VLOOKUP(B32,#REF!,VLOOKUP($F$6,'BASE CONTÁBIL'!N:O,2,FALSE),FALSE),0)))) | L32: =IFERROR(I32*(1+J32%),"") | M32: =IFERROR(IF(B32="","",L32*(1+K32)),"") | N32: =IFERROR(IF(B32="","",IF(F32="","",F32*I32)),"") | O32: =IFERROR(IF(B32="","",IF(F32="","",M32*F32)),"") | P32: =VLOOKUP(B32,#REF!,17,FALSE) -> #REF!
C33: =IFERROR((IF(B33="","",IF($F$6="","Informar UF / Tabela / Prazo de Pagamento",IF($F$9="","Informar UF / Tabela / Prazo de Pagamento",IF($C$9="","Informar UF / Tabela / Prazo de Pagamento",VLOOKUP(B33,'Tabela 130 '!$A$5:$T$1001,2,FALSE)))))),"REF. NÃO CADASTRADA NA TABELA") | D33: =IF('FOLHA DE PEDIDO '!B33="","",IF(C33="REF. NÃO CADASTRADA NA TABELA","",VLOOKUP(B33,'Tabela 130 '!$A$5:$AI$801,3,FALSE))) | G33: =IFERROR(IF(C33="REF. NÃO CADASTRADA NA TABELA","",IF($C$9="","",IF($F$9="","",IF(B33="","",IF($C$9=119,VLOOKUP(B33,'Tabela 130 '!$A$5:$T$2711,MATCH($F$9,'Tabela 130 '!$A$5:$T$5,0),FALSE),IF($C$9=553,VLOOKUP(B33,#REF!,MATCH($F$9,#REF!,0),FALSE),IF($C$9=552,VLOOKUP(B33,#REF!,MATCH($F$9,#REF!,0),FALSE),IF($C$9=551,VLOOKUP(B33,#REF!,MATCH($F$9,#REF!,0),FALSE))))))))),"REF. NÃO CADASTRADA NA TABELA") | I33: =IFERROR(IF(B33=0,"",(G33-(G33*H33))),"") | J33: =IF(B33="","",IF(C33="REF. NÃO CADASTRADA NA TABELA","",VLOOKUP(B33,#REF!,7,FALSE))) | K33: =IF($F$6="","",IF(B33="","",IF(C33="REF. NÃO CADASTRADA NA TABELA","",IFERROR(VLOOKUP(B33,#REF!,VLOOKUP($F$6,'BASE CONTÁBIL'!N:O,2,FALSE),FALSE),0)))) | L33: =IFERROR(I33*(1+J33%),"") | M33: =IFERROR(IF(B33="","",L33*(1+K33)),"") | N33: =IFERROR(IF(B33="","",IF(F33="","",F33*I33)),"") | O33: =IFERROR(IF(B33="","",IF(F33="","",M33*F33)),"") | P33: =VLOOKUP(B33,#REF!,17,FALSE) -> #REF!
C34: =IFERROR((IF(B34="","",IF($F$6="","Informar UF / Tabela / Prazo de Pagamento",IF($F$9="","Informar UF / Tabela / Prazo de Pagamento",IF($C$9="","Informar UF / Tabela / Prazo de Pagamento",VLOOKUP(B34,'Tabela 130 '!$A$5:$T$1001,2,FALSE)))))),"REF. NÃO CADASTRADA NA TABELA") | D34: =IF('FOLHA DE PEDIDO '!B34="","",IF(C34="REF. NÃO CADASTRADA NA TABELA","",VLOOKUP(B34,'Tabela 130 '!$A$5:$AI$801,3,FALSE))) | G34: =IFERROR(IF(C34="REF. NÃO CADASTRADA NA TABELA","",IF($C$9="","",IF($F$9="","",IF(B34="","",IF($C$9=119,VLOOKUP(B34,'Tabela 130 '!$A$5:$T$2711,MATCH($F$9,'Tabela 130 '!$A$5:$T$5,0),FALSE),IF($C$9=553,VLOOKUP(B34,#REF!,MATCH($F$9,#REF!,0),FALSE),IF($C$9=552,VLOOKUP(B34,#REF!,MATCH($F$9,#REF!,0),FALSE),IF($C$9=551,VLOOKUP(B34,#REF!,MATCH($F$9,#REF!,0),FALSE))))))))),"REF. NÃO CADASTRADA NA TABELA") | I34: =IFERROR(IF(B34=0,"",(G34-(G34*H34))),"") | J34: =IF(B34="","",IF(C34="REF. NÃO CADASTRADA NA TABELA","",VLOOKUP(B34,#REF!,7,FALSE))) | K34: =IF($F$6="","",IF(B34="","",IF(C34="REF. NÃO CADASTRADA NA TABELA","",IFERROR(VLOOKUP(B34,#REF!,VLOOKUP($F$6,'BASE CONTÁBIL'!N:O,2,FALSE),FALSE),0)))) | L34: =IFERROR(I34*(1+J34%),"") | M34: =IFERROR(IF(B34="","",L34*(1+K34)),"") | N34: =IFERROR(IF(B34="","",IF(F34="","",F34*I34)),"") | O34: =IFERROR(IF(B34="","",IF(F34="","",M34*F34)),"") | P34: =VLOOKUP(B34,#REF!,17,FALSE) -> #REF!
C35: =IFERROR((IF(B35="","",IF($F$6="","Informar UF / Tabela / Prazo de Pagamento",IF($F$9="","Informar UF / Tabela / Prazo de Pagamento",IF($C$9="","Informar UF / Tabela / Prazo de Pagamento",VLOOKUP(B35,'Tabela 130 '!$A$5:$T$1001,2,FALSE)))))),"REF. NÃO CADASTRADA NA TABELA") | D35: =IF('FOLHA DE PEDIDO '!B35="","",IF(C35="REF. NÃO CADASTRADA NA TABELA","",VLOOKUP(B35,'Tabela 130 '!$A$5:$AI$801,3,FALSE))) | G35: =IFERROR(IF(C35="REF. NÃO CADASTRADA NA TABELA","",IF($C$9="","",IF($F$9="","",IF(B35="","",IF($C$9=119,VLOOKUP(B35,'Tabela 130 '!$A$5:$T$2711,MATCH($F$9,'Tabela 130 '!$A$5:$T$5,0),FALSE),IF($C$9=553,VLOOKUP(B35,#REF!,MATCH($F$9,#REF!,0),FALSE),IF($C$9=552,VLOOKUP(B35,#REF!,MATCH($F$9,#REF!,0),FALSE),IF($C$9=551,VLOOKUP(B35,#REF!,MATCH($F$9,#REF!,0),FALSE))))))))),"REF. NÃO CADASTRADA NA TABELA") | I35: =IFERROR(IF(B35=0,"",(G35-(G35*H35))),"") | J35: =IF(B35="","",IF(C35="REF. NÃO CADASTRADA NA TABELA","",VLOOKUP(B35,#REF!,7,FALSE))) | K35: =IF($F$6="","",IF(B35="","",IF(C35="REF. NÃO CADASTRADA NA TABELA","",IFERROR(VLOOKUP(B35,#REF!,VLOOKUP($F$6,'BASE CONTÁBIL'!N:O,2,FALSE),FALSE),0)))) | L35: =IFERROR(I35*(1+J35%),"") | M35: =IFERROR(IF(B35="","",L35*(1+K35)),"") | N35: =IFERROR(IF(B35="","",IF(F35="","",F35*I35)),"") | O35: =IFERROR(IF(B35="","",IF(F35="","",M35*F35)),"") | P35: =VLOOKUP(B35,#REF!,17,FALSE) -> #REF!
C36: =IFERROR((IF(B36="","",IF($F$6="","Informar UF / Tabela / Prazo de Pagamento",IF($F$9="","Informar UF / Tabela / Prazo de Pagamento",IF($C$9="","Informar UF / Tabela / Prazo de Pagamento",VLOOKUP(B36,'Tabela 130 '!$A$5:$T$1001,2,FALSE)))))),"REF. NÃO CADASTRADA NA TABELA") | D36: =IF('FOLHA DE PEDIDO '!B36="","",IF(C36="REF. NÃO CADASTRADA NA TABELA","",VLOOKUP(B36,'Tabela 130 '!$A$5:$AI$801,3,FALSE))) | G36: =IFERROR(IF(C36="REF. NÃO CADASTRADA NA TABELA","",IF($C$9="","",IF($F$9="","",IF(B36="","",IF($C$9=119,VLOOKUP(B36,'Tabela 130 '!$A$5:$T$2711,MATCH($F$9,'Tabela 130 '!$A$5:$T$5,0),FALSE),IF($C$9=553,VLOOKUP(B36,#REF!,MATCH($F$9,#REF!,0),FALSE),IF($C$9=552,VLOOKUP(B36,#REF!,MATCH($F$9,#REF!,0),FALSE),IF($C$9=551,VLOOKUP(B36,#REF!,MATCH($F$9,#REF!,0),FALSE))))))))),"REF. NÃO CADASTRADA NA TABELA") | I36: =IFERROR(IF(B36=0,"",(G36-(G36*H36))),"") | J36: =IF(B36="","",IF(C36="REF. NÃO CADASTRADA NA TABELA","",VLOOKUP(B36,#REF!,7,FALSE))) | K36: =IF($F$6="","",IF(B36="","",IF(C36="REF. NÃO CADASTRADA NA TABELA","",IFERROR(VLOOKUP(B36,#REF!,VLOOKUP($F$6,'BASE CONTÁBIL'!N:O,2,FALSE),FALSE),0)))) | L36: =IFERROR(I36*(1+J36%),"") | M36: =IFERROR(IF(B36="","",L36*(1+K36)),"") | N36: =IFERROR(IF(B36="","",IF(F36="","",F36*I36)),"") | O36: =IFERROR(IF(B36="","",IF(F36="","",M36*F36)),"") | P36: =VLOOKUP(B36,#REF!,17,FALSE) -> #REF!
C37: =IFERROR((IF(B37="","",IF($F$6="","Informar UF / Tabela / Prazo de Pagamento",IF($F$9="","Informar UF / Tabela / Prazo de Pagamento",IF($C$9="","Informar UF / Tabela / Prazo de Pagamento",VLOOKUP(B37,'Tabela 130 '!$A$5:$T$1001,2,FALSE)))))),"REF. NÃO CADASTRADA NA TABELA") | D37: =IF('FOLHA DE PEDIDO '!B37="","",IF(C37="REF. NÃO CADASTRADA NA TABELA","",VLOOKUP(B37,'Tabela 130 '!$A$5:$AI$801,3,FALSE))) | G37: =IFERROR(IF(C37="REF. NÃO CADASTRADA NA TABELA","",IF($C$9="","",IF($F$9="","",IF(B37="","",IF($C$9=119,VLOOKUP(B37,'Tabela 130 '!$A$5:$T$2711,MATCH($F$9,'Tabela 130 '!$A$5:$T$5,0),FALSE),IF($C$9=553,VLOOKUP(B37,#REF!,MATCH($F$9,#REF!,0),FALSE),IF($C$9=552,VLOOKUP(B37,#REF!,MATCH($F$9,#REF!,0),FALSE),IF($C$9=551,VLOOKUP(B37,#REF!,MATCH($F$9,#REF!,0),FALSE))))))))),"REF. NÃO CADASTRADA NA TABELA") | I37: =IFERROR(IF(B37=0,"",(G37-(G37*H37))),"") | J37: =IF(B37="","",IF(C37="REF. NÃO CADASTRADA NA TABELA","",VLOOKUP(B37,#REF!,7,FALSE))) | K37: =IF($F$6="","",IF(B37="","",IF(C37="REF. NÃO CADASTRADA NA TABELA","",IFERROR(VLOOKUP(B37,#REF!,VLOOKUP($F$6,'BASE CONTÁBIL'!N:O,2,FALSE),FALSE),0)))) | L37: =IFERROR(I37*(1+J37%),"") | M37: =IFERROR(IF(B37="","",L37*(1+K37)),"") | N37: =IFERROR(IF(B37="","",IF(F37="","",F37*I37)),"") | O37: =IFERROR(IF(B37="","",IF(F37="","",M37*F37)),"") | P37: =VLOOKUP(B37,#REF!,17,FALSE) -> #REF!
... C328: =IFERROR((IF(B328="","",IF($F$6="","Informar UF / Tabela / Prazo de Pagamento",IF($F$9="","Informar UF / Tabela / Prazo de Pagamento",IF($C$9="","Informar UF / Tabela / Prazo de Pagamento",VLOOKUP(B328,'Tabela 130 '!$A$5:$T$1001,2,FALSE)))))),"REF. NÃO CADASTRADA NA TABELA") | D328: =IF('FOLHA DE PEDIDO '!B328="","",IF(C328="REF. NÃO CADASTRADA NA TABELA","",VLOOKUP(B328,'Tabela 130 '!$A$5:$AI$801,3,FALSE))) | G328: =IFERROR(IF(C328="REF. NÃO CADASTRADA NA TABELA","",IF($C$9="","",IF($F$9="","",IF(B328="","",IF($C$9=119,VLOOKUP(B328,'Tabela 130 '!$A$5:$T$2711,MATCH($F$9,'Tabela 130 '!$A$5:$T$5,0),FALSE),IF($C$9=553,VLOOKUP(B328,#REF!,MATCH($F$9,#REF!,0),FALSE),IF($C$9=552,VLOOKUP(B328,#REF!,MATCH($F$9,#REF!,0),FALSE),IF($C$9=551,VLOOKUP(B328,#REF!,MATCH($F$9,#REF!,0),FALSE))))))))),"REF. NÃO CADASTRADA NA TABELA") | I328: =IFERROR(IF(B328=0,"",(G328-(G328*H328))),"") | J328: =IF(B328="","",IF(C328="REF. NÃO CADASTRADA NA TABELA","",VLOOKUP(B328,#REF!,7,FALSE))) | K328: =IF($F$6="","",IF(B328="","",IF(C328="REF. NÃO CADASTRADA NA TABELA","",IFERROR(VLOOKUP(B328,#REF!,VLOOKUP($F$6,'BASE CONTÁBIL'!N:O,2,FALSE),FALSE),0)))) | L328: =IFERROR(I328*(1+J328%),"") | M328: =IFERROR(IF(B328="","",L328*(1+K328)),"") | N328: =IFERROR(IF(B328="","",IF(F328="","",F328*I328)),"") | O328: =IFERROR(IF(B328="","",IF(F328="","",M328*F328)),"") | P328: =VLOOKUP(B328,#REF!,17,FALSE) -> #REF!
B330: 8097
B331: 8098
B332: 8099
...

Sheet Tabela 130 
A1: L
J4: PREÇOS UNITÁRIOS
A5: Referência | B5: Descrição | C5: EMB. | D5: À Vista | E5: 14 | F5: 21 | G5: 28 | H5: 35 | I5: 42 | J5: 49 | K5: 56 | L5: 60 | M5: 75 | N5: 90 | O5: MG | P5: PR | Q5: RJ | R5: RS | S5: SP | T5: IPI
A6: 121 | B6: CAIXA RETANGULAR 3,5 L. | C6: 6 | D6: 17.69 | E6: 17.84 | F6: 17.92 | G6: 18 | H6: 18.07 | I6: 18.16 | J6: 18.23 | K6: 18.32 | L6: 18.36 | M6: 18.54 | N6: 18.71
A7: 122 | B7: CAIXA RETANGULAR 6,5 L. | C7: 6 | D7: 25.91 | E7: 26.14 | F7: 26.25 | G7: 26.37 | H7: 26.49 | I7: 26.6 | J7: 26.72 | K7: 26.84 | L7: 26.9 | M7: 27.16 | N7: 27.41
A8: 123 | B8: CAIXA RETANGULAR 11 L. | C8: 6 | D8: 43.73 | E8: 44.12 | F8: 44.31 | G8: 44.51 | H8: 44.71 | I8: 44.9 | J8: 45.1 | K8: 45.29 | L8: 45.41 | M8: 45.84 | N8: 46.27
A9: 125 | B9: BACIA REDONDA 2,5 L. | C9: 12 | D9: 6.49 | E9: 6.54 | F9: 6.57 | G9: 6.6 | H9: 6.62 | I9: 6.66 | J9: 6.69 | K9: 6.72 | L9: 6.73 | M9: 6.79 | N9: 6.86
A10: 126 | B10: BACIA REDONDA 5,5 L. | C10: 12 | D10: 9.12 | E10: 9.2 | F10: 9.23 | G10: 9.28 | H10: 9.32 | I10: 9.36 | J10: 9.4 | K10: 9.45 | L10: 9.47 | M10: 9.55 | N10: 9.65
A11: 127 | B11: BACIA REDONDA 11 L. | C11: 6 | D11: 17.75 | E11: 17.91 | F11: 17.99 | G11: 18.07 | H11: 18.15 | I11: 18.23 | J11: 18.31 | K11: 18.39 | L11: 18.44 | M11: 18.61 | N11: 18.79
A12: 128 | B12: BACIA REDONDA 19,5 L. | C12: 6 | D12: 27.29 | E12: 27.52 | F12: 27.65 | G12: 27.76 | H12: 27.89 | I12: 28.01 | J12: 28.14 | K12: 28.25 | L12: 28.33 | M12: 28.6 | N12: 28.87
A13: 150 | B13: BACIA LISA 2,5 L | C13: 12 | D13: 3.9 | E13: 3.93 | F13: 3.94 | G13: 3.96 | H13: 3.98 | I13: 3.99 | J13: 4.02 | K13: 4.04 | L13: 4.05 | M13: 4.08 | N13: 4.12
A14: 160 | B14: BALDE 8.0 LTS. | C14: 12 | D14: 13.57 | E14: 13.7 | F14: 13.75 | G14: 13.81 | H14: 13.88 | I14: 13.93 | J14: 13.99 | K14: 14.06 | L14: 14.09 | M14: 14.23 | N14: 14.36
A15: 160LP | B15: BALDE RECYCLE 8L. | C15: 12 | D15: 11.64 | E15: 11.75 | F15: 11.79 | G15: 11.84 | H15: 11.9 | I15: 11.95 | J15: 12 | K15: 12.06 | L15: 12.09 | M15: 12.2 | N15: 12.31
A16: 162 | B16: BALDE 16 LTS. | C16: 6 | D16: 25.98 | E16: 26.21 | F16: 26.33 | G16: 26.44 | H16: 26.56 | I16: 26.68 | J16: 26.8 | K16: 26.91 | L16: 26.98 | M16: 27.23 | N16: 27.49
A17: 163 | B17: BALDE 10 LTS. | C17: 12 | D17: 15.74 | E17: 15.88 | F17: 15.94 | G17: 16.02 | H17: 16.09 | I17: 16.16 | J17: 16.23 | K17: 16.31 | L17: 16.35 | M17: 16.5 | N17: 16.66
A18: 163LP | B18: BALDE RECYCLE 1OL. | C18: 12 | D18: 12.27 | E18: 12.38 | F18: 12.43 | G18: 12.49 | H18: 12.55 | I18: 12.6 | J18: 12.65 | K18: 12.71 | L18: 12.74 | M18: 12.87 | N18: 12.98
A19: 164 | B19: LIXAO 97 LITROS. | C19: 4 | D19: 136.96 | E19: 138.17 | F19: 138.78 | G19: 139.39 | H19: 140 | I19: 140.62 | J19: 141.24 | K19: 141.86 | L19: 142.21 | M19: 143.56 | N19: 144.91
A20: 164AM | B20: LIXEIRA 97 LITROS AMARELA | C20: 4 | D20: 171.37 | E20: 172.88 | F20: 173.65 | G20: 174.4 | H20: 175.18 | I20: 175.95 | J20: 176.73 | K20: 177.5 | L20: 177.95 | M20: 179.63 | N20: 181.33
A21: 164AZ | B21: LIXEIRA 97 LITROS AZUL. | C21: 4 | D21: 171.37 | E21: 172.88 | F21: 173.65 | G21: 174.4 | H21: 175.18 | I21: 175.95 | J21: 176.73 | K21: 177.5 | L21: 177.95 | M21: 179.63 | N21: 181.33
A22: 164LP | B22: LIXEIRA 97 LITROS PRETO. | C22: 4 | D22: 109.55 | E22: 110.5 | F22: 110.99 | G22: 111.48 | H22: 111.97 | I22: 112.46 | J22: 112.96 | K22: 113.45 | L22: 113.74 | M22: 114.82 | N22: 115.9
A23: 164VD | B23: LIXEIRA 97 LITROS VERDE. | C23: 4 | D23: 171.37 | E23: 172.88 | F23: 173.65 | G23: 174.4 | H23: 175.18 | I23: 175.95 | J23: 176.73 | K23: 177.5 | L23: 177.95 | M23: 179.63 | N23: 181.33
A24: 164VM | B24: LIXEIRA 97 LITROS VERMELH | C24: 4 | D24: 171.37 | E24: 172.88 | F24: 173.65 | G24: 174.4 | H24: 175.18 | I24: 175.95 | J24: 176.73 | K24: 177.5 | L24: 177.95 | M24: 179.63 | N24: 181.33
A25: 167 | B25: CESTO PARA ROUPAS 35 L. | C25: 6 | D25: 24.54 | E25: 24.76 | F25: 24.87 | G25: 24.97 | H25: 25.08 | I25: 25.2 | J25: 25.3 | K25: 25.42 | L25: 25.49 | M25: 25.72 | N25: 25.96
A26: 167LP | B26: CESTO PARA ROUPAS 35 L. | C26: 6 | D26: 17.69 | E26: 17.84 | F26: 17.92 | G26: 18 | H26: 18.07 | I26: 18.16 | J26: 18.23 | K26: 18.32 | L26: 18.36 | M26: 18.54 | N26: 18.71
A27: 168 | B27: BALDE 20 LITROS. | C27: 6 | D27: 27.29 | E27: 27.52 | F27: 27.65 | G27: 27.76 | H27: 27.89 | I27: 28.01 | J27: 28.14 | K27: 28.25 | L27: 28.33 | M27: 28.6 | N27: 28.87
A28: 170 | B28: LIXEIRA BASCULANTE P/PIA. | C28: 6 | D28: 12.2 | E28: 12.31 | F28: 12.36 | G28: 12.42 | H28: 12.47 | I28: 12.52 | J28: 12.58 | K28: 12.64 | L28: 12.67 | M28: 12.79 | N28: 12.91
A29: 171 | B29: LIXEIRA P/ PIA. | C29: 12 | D29: 9.03 | E29: 9.12 | F29: 9.16 | G29: 9.19 | H29: 9.23 | I29: 9.28 | J29: 9.32 | K29: 9.36 | L29: 9.38 | M29: 9.47 | N29: 9.56
A30: 173 | B30: CESTO P/ PAPEL. | C30: 12 | D30: 6.84 | E30: 6.9 | F30: 6.93 | G30: 6.97 | H30: 7 | I30: 7.03 | J30: 7.05 | K30: 7.08 | L30: 7.1 | M30: 7.17 | N30: 7.24
A31: 175 | B31: LIXEIRA 35 LITROS. | C31: 4 | D31: 54.7 | E31: 55.19 | F31: 55.42 | G31: 55.67 | H31: 55.91 | I31: 56.16 | J31: 56.41 | K31: 56.66 | L31: 56.8 | M31: 57.34 | N31: 57.88
A32: 177 | B32: LIXEIRA 62 LITROS. | C32: 4 | D32: 75.4 | E32: 76.07 | F32: 76.4 | G32: 76.74 | H32: 77.07 | I32: 77.41 | J32: 77.76 | K32: 78.1 | L32: 78.3 | M32: 79.03 | N32: 79.78
A33: 179 | B33: LIXEIRA BASCULANTE 12 LTR | C33: 6 | D33: 27.29 | E33: 27.52 | F33: 27.65 | G33: 27.76 | H33: 27.89 | I33: 28.01 | J33: 28.14 | K33: 28.25 | L33: 28.33 | M33: 28.6 | N33: 28.87
A34: 182 | B34: LIXEIRA C/PEDAL 13 LITROS | C34: 6 | D34: 35.51 | E34: 35.83 | F34: 35.98 | G34: 36.14 | H34: 36.3 | I34: 36.45 | J34: 36.61 | K34: 36.77 | L34: 36.87 | M34: 37.22 | N34: 37.57
A35: 183 | B35: LIXEIRA C/PEDAL 6,5L | C35: 6 | D35: 24.54 | E35: 24.76 | F35: 24.87 | G35: 24.97 | H35: 25.08 | I35: 25.2 | J35: 25.3 | K35: 25.42 | L35: 25.49 | M35: 25.72 | N35: 25.96
A36: 187 | B36: LIXEIRA RETRATIL 1,4 L. | C36: 12 | D36: 8.91 | E36: 8.99 | F36: 9.03 | G36: 9.07 | H36: 9.11 | I36: 9.15 | J36: 9.19 | K36: 9.23 | L36: 9.25 | M36: 9.34 | N36: 9.43
A37: 189 | B37: LIXEIRA RETRATIL 4,1 L. | C37: 9 | D37: 15.02 | E37: 15.14 | F37: 15.21 | G37: 15.28 | H37: 15.35 | I37: 15.41 | J37: 15.49 | K37: 15.55 | L37: 15.59 | M37: 15.74 | N37: 15.88
A38: 191 | B38: POTE HERMETICO 0,5 L. | C38: 12 | D38: 5.06 | E38: 5.1 | F38: 5.12 | G38: 5.14 | H38: 5.18 | I38: 5.2 | J38: 5.22 | K38: 5.24 | L38: 5.25 | M38: 5.3 | N38: 5.36
... A56: 293 | B56: ORGANIZADOR 12,5 LITROS. | C56: 4 | D56: 35.51 | E56: 35.83 | F56: 35.98 | G56: 36.14 | H56: 36.3 | I56: 36.45 | J56: 36.61 | K56: 36.77 | L56: 36.87 | M56: 37.22 | N56: 37.57
A57: 293OC | B57: ORGANIZADOR 12,5 LITROS. | C57: 4 | D57: 25.91 | E57: 26.14 | F57: 26.25 | G57: 26.37 | H57: 26.49 | I57: 26.6 | J57: 26.72 | K57: 26.84 | L57: 26.9 | M57: 27.16 | N57: 27.41
A58: 295 | B58: ORGANIZADOR 38 LITROS. | C58: 4 | D58: 61.56 | E58: 62.1 | F58: 62.38 | G58: 62.64 | H58: 62.92 | I58: 63.2 | J58: 63.47 | K58: 63.76 | L58: 63.92 | M58: 64.52 | N58: 65.14
A59: 295OC | B59: ORGANIZADOR 38 LITROS. | C59: 4 | D59: 40.99 | E59: 41.35 | F59: 41.54 | G59: 41.72 | H59: 41.9 | I59: 42.09 | J59: 42.27 | K59: 42.46 | L59: 42.57 | M59: 42.96 | N59: 43.38
...

Sheet BASE CONTÁBIL
A1: CLASSIFICAÇÃO FISCAL | B1: REVENDA | G1: NACIONAL
B2: MG | C2: PR | D2: RJ | E2: RS | F2: SP | G2: MG | H2: PR | I2: RJ | J2: RS | K2: SP | N2: MG | O2: 32
A3: 39221000 | B3: 0 | C3: 0 | D3: 0 | E3: 0 | F3: 0 | G3: 0 | H3: 0 | I3: 0 | J3: 0 | K3: 0 | N3: PR | O3: 33
A4: 39241000 | B4: 0.2526 | C4: 0.3673 | D4: 0.3817 | E4: 0 | F4: 0.3231 | G4: 0.1781 | H4: 0.2584 | I4: 0.2724 | J4: 0 | K4: 0.2179 | N4: RJ | O4: 34
A5: 39249000 | B5: 0 | C5: 0 | D5: 0 | E5: 0 | F5: 0 | G5: 0 | H5: 0 | I5: 0 | J5: 0 | K5: 0 | N5: RS | O5: 35
A6: 39269090 | B6: 0 | C6: 0 | D6: 0 | E6: 0 | F6: 0 | G6: 0 | H6: 0 | I6: 0 | J6: 0 | K6: 0 | N6: SP | O6: 36
A7: 39232910 | B7: 0 | C7: 0 | D7: 0 | E7: 0 | F7: 0 | G7: 0 | H7: 0 | I7: 0 | J7: 0 | K7: 0
A8: 42010090 | B8: 0 | C8: 0 | D8: 0 | E8: 0 | F8: 0 | G8: 0 | H8: 0 | I8: 0 | J8: 0 | K8: 0
A9: 42022220 | B9: 0 | C9: 0 | D9: 0 | E9: 0 | F9: 0 | G9: 0 | H9: 0 | I9: 0 | J9: 0 | K9: 0
A10: 42022900 | B10: 0 | C10: 0 | D10: 0 | E10: 0 | F10: 0 | G10: 0 | H10: 0 | I10: 0 | J10: 0 | K10: 0
A11: 44191900 | B11: 0 | C11: 0 | D11: 0 | E11: 0 | F11: 0 | G11: 0 | H11: 0 | I11: 0 | J11: 0 | K11: 0
A12: 44191100 | B12: 0 | C12: 0 | D12: 0 | E12: 0 | F12: 0 | G12: 0 | H12: 0 | I12: 0 | J12: 0 | K12: 0
A13: 48191000 | B13: 0 | C13: 0 | D13: 0 | E13: 0 | F13: 0 | G13: 0 | H13: 0 | I13: 0 | J13: 0 | K13: 0
A14: 57023200 | B14: 0 | C14: 0 | D14: 0 | E14: 0 | F14: 0 | G14: 0 | H14: 0 | I14: 0 | J14: 0 | K14: 0
A15: 61169300 | B15: 0 | C15: 0 | D15: 0 | E15: 0 | F15: 0 | G15: 0 | H15: 0 | I15: 0 | J15: 0 | K15: 0
A16: 63079090 | B16: 0 | C16: 0 | D16: 0 | E16: 0 | F16: 0 | G16: 0 | H16: 0 | I16: 0 | J16: 0 | K16: 0
A17: 70109012 | B17: 0 | C17: 0 | D17: 0 | E17: 0 | F17: 0 | G17: 0 | H17: 0 | I17: 0 | J17: 0 | K17: 0
A18: 70133700 | B18: 0.3223 | C18: 0.3302 | D18: 0.3519 | E18: 0 | F18: 0.2773 | G18: 0 | H18: 0 | I18: 0 | J18: 0 | K18: 0
... A32: 70132800 | B32: 0.3223 | C32: 0.3451 | D32: 0.3756 | E32: 0 | F32: 0.3234 | G32: 0 | H32: 0 | I32: 0 | J32: 0 | K32: 0
A33: 70134210 | B33: 32,35% | C33: 0.344 | D33: 0.3756 | E33: 0.2897 | F33: 0.3223 | G33: 0 | H33: 0 | I33: 0 | J33: 0 | K33: 0
A34: 70109090 | B34: 0 | C34: 0 | D34: 0 | E34: 0 | F34: 0 | G34: 0 | H34: 0 | I34: 0 | J34: 0 | K34: 0
A35: 70109022 | B35: 0 | C35: 0 | D35: 0 | E35: 0 | F35: 0 | G35: 0 | H35: 0 | I35: 0 | J35: 0 | K35: 0
A36: 70109021 | B36: 0 | C36: 0 | D36: 0 | E36: 0 | F36: 0 | G36: 0 | H36: 0 | I36: 0 | J36: 0 | K36: 0
C38: Comparativo ST por UF
C40: NCM | D40: MVA/IVA ORIG. | E40: MVA/IVA AJUST | F40: UF | G40: CUSTO ST
C41: 3924.10.00 | D41: 0.5 | E41: 0.7561 | F41: MG | G41: 0.2785
B42: NACIONAL | C42: 3924.10.00 | D42: 0.5 | E42: 0.6098 | F42: MG | G42: 0.1771
C43: 7013.28.00 | D43: 0.7 | E43: 0.9902 | F43: MG | G43: 0.3218
C44: 7013.37.00 | D44: 0.7 | E44: 0.9902 | F44: MG | G44: 0.3218
C45: 7013.42.90 | D45: 0.7 | E45: 0.9902 | F45: MG | G45: 0.3207
C46: 7013.49.00 | D46: 0.7 | E46: 0.9902 | F46: MG | G46: 0.3207
C47: 8509.40.90 | D47: 0.4 | E47: 0.639 | F47: MG | G47: 0.2575
C48: 8516.79.90 | D48: 0.4 | E48: 0.639 | F48: MG | G48: 0.2586
B49: NACIONAL | C49: 3924.10.00 | D49: 0.5 | E49: 0.6807 | F49: MS | G49: 0.22
C50: 3924.10.00 | D50: 0.5 | E50: 0.7349 | F50: MS | G50: 0.2574
C51: 3924.10.00 | D51: 0.7977 | E51: 1.1046 | F51: PR | G51: 0.3413
C52: 3924.10.00 | D52: 0.7977 | E52: 0.9292 | F52: PR | G52: 0.2346
B53: NACIONAL SN | C53: 3924.10.00 | D53: 0.2393 | E53: 0.2788 | F53: PR | G53: 0.1175
B54: IMPORTADO SN | C54: 3924.10.00 | D54: 0.2393 | E54: 0.3314 | F54: PR | G54: 0.2021
C55: 7013.28.00 | D55: 0.6943 | E55: 0.9836 | F55: PR | G55: 0.3206
...
